<?xml version="1.0"?>
<robot name="TQD_Robot">


    <!-- Robot Footprint -->
    <link name="base_footprint" />

    <joint name="base_joint" type="fixed">
        <parent link="base_footprint" />
        <child link="base_link" />
        <origin xyz="0.0 0.0 0.01" rpy="0 0 0" />
    </joint>


    <!-- base link -->
    <link name="base_link">
        <visual>
            <origin rpy="0 0 0" xyz="0 0 0" />
            <geometry>
                <box size="0.09 0.06 0.01" />
            </geometry>
            <material name="blue">
                <color rgba="0.0 0.0 0.8 1.0" />
            </material>
        </visual>
        <collision>
            <origin rpy="0 0 0" xyz="0 0 0" />
            <geometry>
                <box size="0.09 0.06 0.01" />
            </geometry>
            <material name="green">
                <color rgba="0.0 0.8 0.0 1.0" />
            </material>
        </collision>
        <inertial>
            <origin rpy="1.5707963267948966 0 1.5707963267948966" xyz="0 0 0" />
            <mass value="0.4" />
            <inertia ixx="0.0001233333333333333" ixy="0.0" ixz="0.0" iyy="0.00038999999999999994"
                iyz="0.0" izz="0.0002733333333333333" />
        </inertial>
    </link>


    <!-- laser link -->
    <link name="laser_link">
        <visual>
            <origin rpy="0 0 0" xyz="0 0 0" />
            <geometry>
                <cylinder length="0.01" radius="0.005" />
            </geometry>
            <material name="blue">
                <color rgba="0.0 0.0 0.8 1.0" />
            </material>
        </visual>
        <collision>
            <origin rpy="0 0 0" xyz="0 0 0" />
            <geometry>
                <cylinder length="0.01" radius="0.005" />
            </geometry>
            <material name="blue">
                <color rgba="0.0 0.0 0.8 1.0" />
            </material>
        </collision>
        <inertial>
            <origin rpy="1.5707963267948966 0 0" xyz="0 0 0" />
            <mass value="0.1" />
            <inertia ixx="1.4583333333333333e-06" ixy="0" ixz="0" iyy="1.4583333333333333e-06"
                iyz="0" izz="1.25e-06" />
        </inertial>
    </link>

    <!-- laser joint -->
    <joint name="laser_joint" type="fixed">
        <parent link="base_link" />
        <child link="laser_link" />
        <origin xyz="0.025 0 0.01" />
    </joint>

    <!-- camera link -->
    <link name="camera_link">
        <visual>
            <origin rpy="0 0 0" xyz="0 0 0" />
            <geometry>
                <box size="0.01 0.01 0.01" />
            </geometry>
            <material name="blue">
                <color rgba="0.0 0.0 0.8 1.0" />
            </material>
        </visual>
        <collision>
            <origin rpy="0 0 0" xyz="0 0 0" />
            <geometry>
                <box size="0.01 0.01 0.01" />
            </geometry>
            <material name="green">
                <color rgba="0.0 0.8 0.0 1.0" />
            </material>
        </collision>
        <inertial>
            <origin rpy="1.5707963267948966 0 1.5707963267948966" xyz="0 0 0" />
            <mass value="0.1" />
            <inertia ixx="1.6666666666666667e-06" ixy="0.0" ixz="0.0" iyy="1.6666666666666667e-06"
                iyz="0.0" izz="1.6666666666666667e-06" />
        </inertial>
    </link>

    <!-- camera joint -->
    <joint name="camera_joint" type="fixed">
        <parent link="base_link" />
        <child link="camera_link" />
        <origin xyz="0.025 0.0 0.04" />
    </joint>

    <!-- imu link -->
    <link name="imu_link">
        <visual>
            <origin rpy="0 0 0" xyz="0 0 0" />
            <geometry>
                <box size="0.01 0.01 0.01" />
            </geometry>
            <material name="blue">
                <color rgba="0.0 0.0 0.8 1.0" />
            </material>
        </visual>
        <collision>
            <origin rpy="0 0 0" xyz="0 0 0" />
            <geometry>
                <box size="0.01 0.01 0.01" />
            </geometry>
            <material name="green">
                <color rgba="0.0 0.8 0.0 1.0" />
            </material>
        </collision>
        <inertial>
            <origin rpy="1.5707963267948966 0 1.5707963267948966" xyz="0 0 0" />
            <mass value="0.1" />
            <inertia ixx="1.6666666666666667e-06" ixy="0.0" ixz="0.0" iyy="1.6666666666666667e-06"
                iyz="0.0" izz="1.6666666666666667e-06" />
        </inertial>
    </link>

    <!-- imu joint -->
    <joint name="imu_joint" type="fixed">
        <parent link="base_link" />
        <child link="imu_link" />
        <origin xyz="0 0 0" />
    </joint>

    <!-- four wheels -->
    <link name="lf_wheel_link">
        <visual>
            <origin rpy="1.57079 0 0" xyz="0 0 0" />
            <geometry>
                <cylinder length="0.01" radius="0.01" />
            </geometry>
            <material name="blue">
                <color rgba="0.0 0.0 0.8 1.0" />
            </material>
        </visual>
        <collision>
            <origin rpy="1.57079 0 0" xyz="0 0 0" />
            <geometry>
                <cylinder length="0.01" radius="0.01" />
            </geometry>
            <material name="blue">
                <color rgba="0.0 0.0 0.8 1.0" />
            </material>
        </collision>
        <inertial>
            <origin rpy="1.5707963267948966 0 0" xyz="0 0 0" />
            <mass value="0.1" />
            <inertia ixx="3.333333333333333e-06" ixy="0" ixz="0" iyy="3.333333333333333e-06" iyz="0"
                izz="5e-06" />
        </inertial>
    </link>
    <link name="rf_wheel_link">
        <visual>
            <origin rpy="1.57079 0 0" xyz="0 0 0" />
            <geometry>
                <cylinder length="0.01" radius="0.01" />
            </geometry>
            <material name="blue">
                <color rgba="0.0 0.0 0.8 1.0" />
            </material>
        </visual>
        <collision>
            <origin rpy="1.57079 0 0" xyz="0 0 0" />
            <geometry>
                <cylinder length="0.01" radius="0.01" />
            </geometry>
            <material name="blue">
                <color rgba="0.0 0.0 0.8 1.0" />
            </material>
        </collision>
        <inertial>
            <origin rpy="1.5707963267948966 0 0" xyz="0 0 0" />
            <mass value="0.1" />
            <inertia ixx="3.333333333333333e-06" ixy="0" ixz="0" iyy="3.333333333333333e-06" iyz="0"
                izz="5e-06" />
        </inertial>
    </link>
    <link name="lr_wheel_link">
        <visual>
            <origin rpy="1.57079 0 0" xyz="0 0 0" />
            <geometry>
                <cylinder length="0.01" radius="0.01" />
            </geometry>
            <material name="blue">
                <color rgba="0.0 0.0 0.8 1.0" />
            </material>
        </visual>
        <collision>
            <origin rpy="1.57079 0 0" xyz="0 0 0" />
            <geometry>
                <cylinder length="0.01" radius="0.01" />
            </geometry>
            <material name="blue">
                <color rgba="0.0 0.0 0.8 1.0" />
            </material>
        </collision>
        <inertial>
            <origin rpy="1.5707963267948966 0 0" xyz="0 0 0" />
            <mass value="0.1" />
            <inertia ixx="3.333333333333333e-06" ixy="0" ixz="0" iyy="3.333333333333333e-06" iyz="0"
                izz="5e-06" />
        </inertial>
    </link>
    <link name="rr_wheel_link">
        <visual>
            <origin rpy="1.57079 0 0" xyz="0 0 0" />
            <geometry>
                <cylinder length="0.01" radius="0.01" />
            </geometry>
            <material name="blue">
                <color rgba="0.0 0.0 0.8 1.0" />
            </material>
        </visual>
        <collision>
            <origin rpy="1.57079 0 0" xyz="0 0 0" />
            <geometry>
                <cylinder length="0.01" radius="0.01" />
            </geometry>
            <material name="blue">
                <color rgba="0.0 0.0 0.8 1.0" />
            </material>
        </collision>
        <inertial>
            <origin rpy="1.5707963267948966 0 0" xyz="0 0 0" />
            <mass value="0.1" />
            <inertia ixx="3.333333333333333e-06" ixy="0" ixz="0" iyy="3.333333333333333e-06" iyz="0"
                izz="5e-06" />
        </inertial>
    </link>


    <joint name="lf_wheel_joint" type="continuous">
        <!-- left front-->
        <parent link="base_link" />
        <child link="lf_wheel_link" />
        <origin xyz="0.005 0.035 0" />
        <axis xyz="0 1 0" />
    </joint>

    <joint name="rf_wheel_joint" type="continuous">
        <!-- right front-->
        <parent link="base_link" />
        <child link="rf_wheel_link" />
        <origin xyz="0.005 -0.035 0" />
        <axis xyz="0 1 0" />
    </joint>

    <joint name="lr_wheel_joint" type="continuous">
        <!-- left rear-->
        <parent link="base_link" />
        <child link="lr_wheel_link" />
        <origin xyz="-0.025 0.035 0" />
        <axis xyz="0 1 0" />
    </joint>

    <joint name="rr_wheel_joint" type="continuous">
        <!-- right rear-->
        <parent link="base_link" />
        <child link="rr_wheel_link" />
        <origin xyz="-0.025 -0.035 0" />
        <axis xyz="0 1 0" />
    </joint>


    <gazebo reference="base_link">
        <material>Gazebo/Blue</material>
    </gazebo>
    <gazebo reference="laser_link">
        <material>Gazebo/Black</material>
    </gazebo>
    <gazebo reference="camera_link">
        <material>Gazebo/Red</material>
    </gazebo>
    <gazebo reference="lf_wheel_link">
        <material>Gazebo/Red</material>
        <mu1 value="1.5"/>
        <mu2 value="1.5"/>
        <kp value="1000000.0" />
        <kd value="1.5" />
    </gazebo>
    <gazebo reference="rf_wheel_link">
        <material>Gazebo/Green</material>
        <mu1 value="1.5"/>
        <mu2 value="1.5"/>
        <kp value="1000000.0" />
        <kd value="1.5" />
    </gazebo>
    <gazebo reference="lr_wheel_link">
        <material>Gazebo/Red</material>
        <mu1 value="1.5"/>
        <mu2 value="1.5"/>
        <kp value="1000000.0" />
        <kd value="1.5" />
    </gazebo>
    <gazebo reference="rr_wheel_link">
        <material>Gazebo/Green</material>
        <mu1 value="1.5"/>
        <mu2 value="1.5"/>
        <kp value="1000000.0" />
        <kd value="1.5" />
    </gazebo>


    <gazebo reference="laser_link">
        <sensor name="laser_sensor" type="ray">
            <always_on>true</always_on>
            <visualize>true</visualize>
            <update_rate>120</update_rate>
            <pose>0.025 0 0.01 0 0 0</pose> <!-- 0 0 0.075 0 0 0-->
            <ray>
                <scan>
                    <horizontal>
                        <samples>360</samples>
                        <resolution>1.000000</resolution>
                        <min_angle>-1.570900</min_angle>
                        <max_angle>1.570900</max_angle>
                    </horizontal>
                </scan>
                <range>
                    <min>0.020000</min>
                    <max>3.5</max>
                    <resolution>0.01000</resolution>
                </range>
                <!-- 
                <noise>
                    <type>gaussian</type>
                    <mean>0.0</mean>
                    <stddev>0.01</stddev>
                </noise>
                -->
            </ray>

            <plugin name="laserscan" filename="libgazebo_ros_ray_sensor.so">
                <ros>
                    <!-- <namespace>/tb3</namespace> -->
                    <remapping>~/out:=scan</remapping>
                </ros>
                <output_type>sensor_msgs/LaserScan</output_type>
                <frame_name>laser_link</frame_name>
            </plugin>
        </sensor>
    </gazebo>

    <gazebo reference="camera_link">
        <sensor type="camera" name="camera_urdf">    
            <update_rate>24.0</update_rate>     
            <camera name="head">         
                <horizontal_fov>1.3962634</horizontal_fov>       
                <image>   
                    <width>640</width>           
                    <height>640</height>           
                    <format>R8G8B8</format>        
                </image>        
                <clip>            
                    <near>0.05</near>
                    <far>100</far>  
                </clip>
            </camera>
            <plugin name="camera_controller_urdf" filename="libgazebo_ros_camera.so">
            </plugin>
        </sensor>
    </gazebo>

    <gazebo>
        <plugin name='diff_drive' filename='libgazebo_ros_diff_drive.so'>
            <ros>
                <namespace>/</namespace>
                <remapping>cmd_vel:=cmd_vel</remapping>
                <remapping>odom:=odom</remapping>
            </ros>
            <update_rate>60</update_rate>
            <left_joint>lf_wheel_joint</left_joint>
            <right_joint>rf_wheel_joint</right_joint>

            <wheel_separation>0.07</wheel_separation>
            <wheel_diameter>0.02</wheel_diameter>

            <max_wheel_torque>5</max_wheel_torque>
            <max_wheel_acceleration>1.0</max_wheel_acceleration>

            <publish_odom>true</publish_odom>
            <publish_odom_tf>true</publish_odom_tf>
            <publish_wheel_tf>false</publish_wheel_tf>
            <odometry_frame>odom</odometry_frame>
            <robot_base_frame>base_footprint</robot_base_frame>
        </plugin>

        <plugin name="joint_state" filename="libgazebo_ros_joint_state_publisher.so">
            <ros>
                <remapping>~/out:=joint_states</remapping>
            </ros>
            <update_rate>30</update_rate>
            <joint_name>lf_wheel_joint</joint_name>
            <joint_name>rf_wheel_joint</joint_name>
        </plugin>
    </gazebo>

    <link name="decoration_link">
    <visual>
        <origin rpy="0 0 0" xyz="-0.05 0 0.02" /> <!-- 调整位置到车尾 -->
        <geometry>
            <box size="0.02 0.02 0.02" /> <!-- 装饰物的大小 -->
        </geometry>
        <material name="orange">
            <color rgba="1.0 0.5 0.0 1.0" /> <!-- 橙色装饰物 -->
        </material>
    </visual>
    <collision>
        <!-- 碰撞模型可以和可视模型相同，也可以根据需要设置 -->
        <origin rpy="0 0 0" xyz="-0.05 0 0.02" />
        <geometry>
            <box size="0.012 0.012 0.012" />
        </geometry>
    </collision>
    <inertial>
        <origin rpy="0 0 0" xyz="-0.05 0 0.02" />
        <mass value="0.01" />
        <inertia ixx="1.0e-06" ixy="0" ixz="0" iyy="1.0e-06" iyz="0" izz="1.0e-06" />
    </inertial>
</link>
<joint name="decoration_joint" type="fixed">
    <parent link="base_link" />
    <child link="decoration_link" />
    <origin xyz="0 0 0" />
</joint>
<gazebo reference="decoration_link">
        <material>Gazebo/Red</material>
       
    </gazebo>


</robot>